# 第九章 错误处理

## 9.1 panic! 不可恢复的错误

### Rust错误处理概述

* Rust的可靠性：错误处理
  * 大部分情况下：在编译时提示错误，并处理
* 错误的分类：
  * 可恢复
    * 例如文件未找到，可再次尝试
  * 不可恢复
    * Bug, ；例如访问的索引超出范围
* Rust没有类似异常的机制
  * 可恢复错误，`Result<T, E>`
  * 不可恢复：panic!宏

### 不可恢复的错误与panic!

* 当panic!宏执行：
  * 你的程序会打印一个错误信息
  * 展开（unwind）、清理调用栈（Stack）
  * 退出程序

### 为应对panic，展开或中止(abort)调用栈

* 默认情况下，当panic发生，

  * 程序展开调用栈（工作量大）
    * Rust沿着调用栈往回走
    * 清理每个遇到的函数中的数据
  * 或立即中止调用栈：
    * 不进行清理，直接停止程序
    * 内存需要OS进行清理

* 想让二进制文件更小，把设置从”展开“改为”中止“：

  * 在Cargo.toml中适当的profile部分设置：

     * panic = 'abort'

       ```rust
       [dependencies]
       
       [profile.release]
       panic = 'abort'
       ```

### 不可恢复的错误与panic!

* (例子)

  ```rust
  fn main(){
      //panic!("crash and burn");
  
      let v = vec![1, 2, 3];
  
      v[99];
  }
  ```

* `panic!`可能出现在：

  * 我们写的代码中
  * 我们所依赖的代码中

* 可通过调用panic!的函数的回溯信息来定位引起问题的代码

* 通过设置环境变量RUST_BACKTRACE可得到回溯信息

* 为了获取带有调试信息的回溯，必须启动调试符号（不带 --release）

## 9.2 Result 与可恢复的错误

### Result枚举

```rust
    enum Result<T, E>{
        Ok(T),
        Err(E),
    }
```

* T：操作成功情况下，Ok变体里返回的数据类型
* E：操作失败情况下，Err变体里返回的错误的类型
* （例子）

```rust
use std::fs::File;

fn main(){
    let f = File::open("hello.txt");
}
```

### 处理Result的一种方式：match表达式

* 和Option枚举一样，Result及其变体也是有prelude（预导入模块）带入作用域，因此match前不用写Result::
* （例子）

```rust
use std::fs::File;

fn main(){
    let f = File::open("hello.txt");

    let f = match f {
        Ok(file) => file,
        Err(error) => {
            panic!("Error opening file {:?}", error);
        }
    };
}
```



### 匹配不同的错误

* （例子）

  ```rust
  use std::fs::File;
  use std::io::ErrorKind;
  
  fn main(){
      let f = File::open("hello.txt");
  
      let f = match f {
          Ok(file) => file,
          Err(error) => match error.kind() {
              ErrorKind::NotFound => match File::create("hello.txt") {
                  Ok(fc) => fc,
                  Err(e) => panic!("Error creating file: {:?}", e),
              },
              other_error => panic!("Error opening the file: {:?}", other_error),
          },
      };
  }
  ```

  

* 上例中使用了很多match...
* match很有用，但是很原始
* 闭包（closure）。`Result<T, E>`有很多方法：
  * 它们接收闭包作为参数
  * 使用match实现
  * 使用这些方法会让代码更简洁 （以后讲）

### unwrap

* Unwrap: match表达式的一个快捷方法：

  ```rust
  use std::fs::File;
  
  fn main(){
      let f = File::open("hello.txt").unwrap_or_else(|error|)
  
      let f = match f {
          Ok(file) => file,
          Err(error) => {
              panic!("Error opening the file: {:?}", error),
          }
      };
  
      // let f = File::open("hello.txt").unwrap();代替上面所有代码
  }
  ```

  * 如果Result结果是Ok，返回Ok里面的值
  * 如果Result结果是Err，调用panic!宏

### expect

* expect: 和unwrap类似，但可指定错误信息
* （例子）

```rust
use std::fs::File;

fn main() {
    let f = File::open("hello.txt").expect("无法打开文件 hello.txt");
}
```

## 9.3 Result 与可恢复的错误（下）

### 传播错误

* 将错误返回给调用者

* （例子）

  ```rust
  use std::fs::File;
  
  use std::io::Read;
  
  fn read_username_from_file() -> Result<String, io::Error>{
      let f = File::open("hello.txt");
      
      let mut f = match f {
          Ok(file) => file,
          Err(e) => return Err(e),
      };
      
      let mut s = String::new();
      match f.read_to_string(&mut s) {
          Ok(_) => Ok(s),
          Err(e) => Err(e),
      }
  }
  
  fn main() {
      let result = read_username_from_file();
  }
  ```

### ? 运算符

* ? 运算符：传播错误的一种快捷方式

* （例子）

  ```rust
  use std::fs::File;
  use std::io;
  use std::io::Read;
  
  fn read_username_from_file() -> Result<String, io::Error>{
      let mut f = File::open("hello.txt")?; // 等价于下面这一段
      // let mut f = match File::open("hello.txt"){
      //     Ok(file) => file,
      //     Err(e) => Err(e),
      // };
      let mut s = String::new();
      f.read_to_string(&mut s)?;
      Ok(s)
  }
  
  fn main() {
      let result = read_username_from_file();
  }
  ```

* 如果Result是Ok: Ok种的值就是表达式的结果，然后继续执行程序
* 如果Result是Err：Err就是整个函数的返回值，就像使用了return

### ? 与from函数

* Trait std::convert::From上的from函数
  * 用于错误之间的转换
* 被?所应用的错误，会隐式的被from函数处理
* 当?调用from函数时：
  * 它所接收的错误类型会被转化为当前函数返回类型所定义的错误类型
* 用于：针对不同的错误原因，返回同一种错误类型
  * 只要每个错误类型实现了转换为所返回的错误类型的from函数

### ? 运算符

* (链式调用的例子)

```rust
use std::fs::File;
use std::io;
use std::io::Read;

fn read_username_from_file() -> Result<String, io::Error>{
    let mut s = String::new();
    File::open("hello.txt")?.read_to_string(&mut s)?;
    Ok(s)
}

fn main() {
    let result = read_username_from_file();
}
```

### ? 运算符只能用于返回Result的函数

### ？运算符与main函数

* main函数返回类型是: ()
* main函数的返回类型也可以是: `Result<T, E>`

## 9.4 什么时候应该用panic!

### 总体原则

* 在定义一个可能失败的函数时，优先考虑返回Result
* 否则就panic!

### 编写示例、原型代码、测试

* 可以使用panic!
  * 演示某些概念：unwrap
  * 原型代码：unwrap、expect
  * 测试：unwrap、expect

### 有时你比编译器掌握更多的信息

* 你可以确定Result就是Ok: unwrap

  ```rust
  use std::net::IpAddr;
  
  fn main() {
      let home: IpAddr = "127.0.0,1".parse().unwrap();
  }
  ```

  

### 错误处理的指导性建议

* 当代码最终可能处于损坏状态时，最好使用panic!
* 损坏状态（Bad state）：某些假设、保证、约定或不可变性被打破
  * 例如非法的值、矛盾的值或空缺的值被传入代码
  * 以及下列中的一条：
    * 这种损坏状态并不是与其能够偶尔发生的事情。
    * 在此之后，你的代码如果处于这种损坏状态就无法运行
    * 在您使用的类型中没有一个好的方法来讲这些信息（处于损坏状态）进行编码。

### 场景建议

* 调用你的代码，传入无意义的参数值：panic!
* 调用外部不可控代码，返回非法状态，你无法修复：panic!
* 如果失败是可预期的：Result
* 当你的代码对值进行操作，首先应该验证这些值：panic!

### 为验证创建自定义类型

* （例子）

  ```rust
  fn main{
      loop {
          let guess = "32";
          let guess: i32 = match guess.trim().parse(){
              Ok(num) => num,
              Err(_) => continue,
          };
          
          if guess < 1 || guess > 100 {
              println!("The secret number will be between 1 and 100.");
              continue;
          }
      }
  }
  ```

* 创建新的类型，把验证逻辑放在构造实例的函数里。

（例子）

```rust
pub struct Guess{
    value: i32,
}

impl Guess{
    pub fn new(value: i32) -> Guess{
        if value < 1 || value > 100 {
            panic!("Guess value must be between 1 and 100, got {}", value);
        }

        Guess {value}
    }

    pub fn value(&self) -> i32{
        self.value
    }
}

fn main(){
    loop {
        let guess = "32";
        let guess: i32 = match guess.trim().parse() {
            Ok(num) => num,
            Err(_) => continue,
        };
        
        let guess = Guess::new(guess);
    }
}
```

